Workbook

Sheet Sheet1
A1: TypeRQ | B1: Material | C1: Sloc | D1: Qty | E1: ActualPrice | F1: Mvtype | G1: MVContent | H1: Plant | I1: CostCenter | J1: VendorCode | K1: Note | L1: CountryofOrigin | M1: ItemDecription | N1: RQ_Reset
A2: 2 | B2: D1BB2201A055 | C2: 2020 | D2: 5 | E2: 0.051566454 | F2: 291 | G2: =VLOOKUP(F2,'Master(Ko Xóa)'!$F$2:$H$158,3,0) -> Out | H2: V501 | I2: 1GZB10 | J2: VA005 | L2: Panasonic SVN_Reset | M2: ECQE6333RKF-EN_Reset | N2: RQB-PUR-0722-21
A3: 2 | B3: D1BB4701A317 | C3: 2020 | D3: 5 | E3: 0.051566454 | F3: 291 | G3: =VLOOKUP(F3,'Master(Ko Xóa)'!$F$2:$H$158,3,0) -> Out | H3: V501 | I3: 1GZB10 | J3: VA005 | L3: Panasonic SVN_Reset | M3: ECQE6333RKF-EN_Reset | N3: RQB-PUR-0722-21
A4: 2 | B4: DRC2143T0L | C4: 2020 | D4: 5 | E4: 0.051566454 | F4: 291 | G4: =VLOOKUP(F4,'Master(Ko Xóa)'!$F$2:$H$158,3,0) -> Out | H4: V501 | I4: 1GZB10 | J4: VA005 | L4: Panasonic SVN_Reset | M4: ECQE6333RKF-EN_Reset | N4: RQB-PUR-0722-21
A5: 2 | B5: ERJ3EKF5101V | C5: 2020 | D5: 5 | E5: 0.051566454 | F5: 291 | G5: =VLOOKUP(F5,'Master(Ko Xóa)'!$F$2:$H$158,3,0) -> Out | H5: V501 | I5: 1GZB10 | J5: VA005 | L5: Panasonic SVN_Reset | M5: ECQE6333RKF-EN_Reset | N5: RQB-PUR-0722-21
A6: 2 | B6: ERJ3EKF6200V | C6: 2020 | D6: 5 | E6: 0.051566454 | F6: 291 | G6: =VLOOKUP(F6,'Master(Ko Xóa)'!$F$2:$H$158,3,0) -> Out | H6: V501 | I6: 1GZB10 | J6: VA005 | L6: Panasonic SVN_Reset | M6: ECQE6333RKF-EN_Reset | N6: RQB-PUR-0722-21

Sheet Master(Ko Xóa)
A1: TypeID | D1: TypeID | E1: MVTypeName | G1: Decription | H1: ContentMV
A2: 1 | D2: 1 | E2: Other issue materials201 | F2: 201 | G2: Xuất/Nhập NVL cho mục đích như Gửi hàng mẫu, làm JIG, check ROSH, phân tích, check Assembly,… | H2: Out | K2: =F2 -> 201 | N2: MVTypeName | O2: =VLOOKUP(Sheet1!A2,'Master(Ko Xóa)'!$D$2:$K$158,8,0) -> 291
A3: 2 | D3: 1 | E3: Other issue materials202 | F3: 202 | G3: Xuất/Nhập NVL cho mục đích như Gửi hàng mẫu, làm JIG, check ROSH, phân tích, check Assembly,… | H3: In | I3: =D3 -> 1 | J3: =F3 -> 202 | O3: =VLOOKUP(Sheet1!A2,'Master(Ko Xóa)'!$I$3:$J$147,2,0) -> 292
A4: 3 | D4: 2 | E4: Return materials291 | F4: 291 | G4: Hàng trả lại vendor (Issue debit note) | H4: Out | K4: =F4 -> 291
A5: 4 | D5: 2 | E5: Return materials292 | F5: 292 | G5: Hàng trả lại vendor (Issue debit note) | H5: In | I5: =D5 -> 2 | J5: =F5 -> 292
A6: 5 | D6: 3 | E6: Material shortage201 | F6: 201 | G6: Vendor giao hàng thiếu (Issue debit note) | H6: Out | K6: =F6 -> 201
A7: 6 | D7: 3 | E7: Material shortage202 | F7: 202 | G7: Vendor giao hàng thiếu (Issue debit note) | H7: In | I7: =D7 -> 3 | J7: =F7 -> 202
A8: 7 | D8: 4 | E8: Claim scrap material201 | F8: 201 | G8: Hàng mua từ vendor nhưng NG không trả lại cho vendor, scrap tại PSNV (Issue debit note) | H8: Out | K8: =F8 -> 201
A9: 8 | D9: 4 | E9: Claim scrap material202 | F9: 202 | G9: Hàng mua từ vendor nhưng NG không trả lại cho vendor, scrap tại PSNV (Issue debit note) | H9: In | I9: =D9 -> 4 | J9: =F9 -> 202
A10: 9 | D10: 5 | E10: Claim Scrap Material (Claim transportation compa | F10: mpa | G10: Hàng mua từ vendor nhưng NG do bên vận chuyển, đòi tiền bên vận chuyển | H10: Out | K10: =F10 -> mpa
A11: 10 | D11: 5 | E11: Claim Scrap Material (Claim transportation compa | F11: mpa | G11: Hàng mua từ vendor nhưng NG do bên vận chuyển, đòi tiền bên vận chuyển | H11: In | I11: =D11 -> 5 | J11: =F11 -> mpa
A12: 11 | D12: 6 | E12: Disposition551 | F12: 551 | G12: Hàng NVL hủy do PSNV chịu chi phí | H12: Out | K12: =F12 -> 551
A13: 12 | D13: 6 | E13: Disposition552 | F13: 552 | G13: Hàng NVL hủy do PSNV chịu chi phí | H13: In | I13: =D13 -> 6 | J13: =F13 -> 552
A14: 13 | D14: 7 | E14: Claim scrap halb201 | F14: 201 | G14: Hàng halb bị hỏng do NVL mua từ vendor bị hỏng và scrap tại PSNV (Issue debit note) | H14: Out | K14: =F14 -> 201
A15: 14 | D15: 7 | E15: Claim scrap halb202 | F15: 202 | G15: Hàng halb bị hỏng do NVL mua từ vendor bị hỏng và scrap tại PSNV (Issue debit note) | H15: In | I15: =D15 -> 7 | J15: =F15 -> 202
A16: 15 | D16: 8 | E16: Claim scrap deadstock201 | F16: 201 | G16: Hàng NVL mua của 1 vendor và không dùng nữa vendor khác chịu chi phí và hủy tại PSNV | H16: Out | K16: =F16 -> 201
A17: 16 | D17: 8 | E17: Claim scrap deadstock202 | F17: 202 | G17: Hàng NVL mua của 1 vendor và không dùng nữa vendor khác chịu chi phí và hủy tại PSNV | H17: In | I17: =D17 -> 8 | J17: =F17 -> 202
A18: 17 | D18: 9 | E18: Issue for lending201 | F18: 201 | G18: Xuất HALB cho vendor, sau đó, hàng trả về PSNV và đòi tiền vendor theo Claim scrap half (hợp đồng Lending và General Sanction) | H18: Out | K18: =F18 -> 201
A19: 18 | D19: 9 | E19: Issue for lending202 | F19: 202 | G19: Xuất HALB cho vendor, sau đó, hàng trả về PSNV và đòi tiền vendor theo Claim scrap half (hợp đồng Lending và General Sanction) | H19: In | I19: =D19 -> 9 | J19: =F19 -> 202
A20: 19 | D20: 10 | E20: Sale deadstock201 | F20: 201 | G20: Hàng NVL mua của 1 vendor và không dùng nữa nên xuất bán cho 1 vendor khác | H20: Out | K20: =F20 -> 201
A21: 20 | D21: 10 | E21: Sale deadstock202 | F21: 202 | G21: Hàng NVL mua của 1 vendor và không dùng nữa nên xuất bán cho 1 vendor khác | H21: In | I21: =D21 -> 10 | J21: =F21 -> 202
A22: 21 | D22: 11 | E22: Compensation201 | F22: 201 | G22: Hàng NVL mua về nhưng không dùng do sai thiết kế, vendor chịu chi phí, hủy tại PSNV | H22: Out | K22: =F22 -> 201
A23: 22 | D23: 11 | E23: Compensation202 | F23: 202 | G23: Hàng NVL mua về nhưng không dùng do sai thiết kế, vendor chịu chi phí, hủy tại PSNV | H23: In | I23: =D23 -> 11 | J23: =F23 -> 202
A24: 23 | D24: 12 | E24: Outsourcing201 | F24: 201 | G24: Hàng NVL issue out dùng cho outsourcing | H24: Out | K24: =F24 -> 201
A25: 25 | D25: 12 | E25: Outsourcing202 | F25: 202 | G25: Hàng NVL issue out dùng cho outsourcing | H25: In | I25: =D25 -> 12 | J25: =F25 -> 202
D26: 13 | E26: Claim insurance201 | F26: 201 | G26: Hàng NVL bị hỏng trong quá trình vận chuyển và được bồi thường bảo hiểm | H26: Out | K26: =F26 -> 201
D27: 13 | E27: Claim insurance202 | F27: 202 | G27: Hàng NVL bị hỏng trong quá trình vận chuyển và được bồi thường bảo hiểm | H27: In | I27: =D27 -> 13 | J27: =F27 -> 202
D28: 14 | E28: Issue out for rework201 | F28: 201 | G28: Hàng NVL issue out để reworks (Issue Debitnote) | H28: Out | K28: =F28 -> 201
D29: 14 | E29: Issue out for rework202 | F29: 202 | G29: Hàng NVL issue out để reworks (Issue Debitnote) | H29: In | I29: =D29 -> 14 | J29: =F29 -> 202
D30: 15 | E30: Issue Out For Rework (Not issue Debit Note)201 | F30: 201 | G30: Hàng NVL issue out cho reworks (không Issue Debitnote), hủy tại PSNV | H30: Out | K30: =F30 -> 201
D31: 15 | E31: Issue Out For Rework (Not issue Debit Note)202 | F31: 202 | G31: Hàng NVL issue out cho reworks (không Issue Debitnote), hủy tại PSNV | H31: In | I31: =D31 -> 15 | J31: =F31 -> 202
D32: 16 | E32: Issue sub-materials201 | F32: 201 | G32: Issue NVL phụ cho sản xuất thành phẩm | H32: Out | K32: =F32 -> 201
D33: 16 | E33: Issue sub-materials202 | F33: 202 | G33: Issue NVL phụ cho sản xuất thành phẩm | H33: In | I33: =D33 -> 16 | J33: =F33 -> 202
D34: 16 | E34: Issue Sub-Materials201 | F34: 201 | G34: Issue NVL phụ cho sản xuất thành phẩm | H34: Out | K34: =F34 -> 201
D35: 17 | E35: Post difference end of month701 | F35: 701 | G35: Post difference giữa tồn kho thực tế và hệ thống | H35: In | I35: =D35 -> 17 | J35: =F35 -> 701
D36: 17 | E36: Post difference end of month702 | F36: 702 | G36: Post difference giữa tồn kho thực tế và hệ thống | H36: Out | K36: =F36 -> 702
D37: 18 | E37: Post difference outsourcing701 | F37: 701 | G37: Post difference giữa tồn kho thực tế và hệ thống của kho nhà thầu phụ | H37: In | I37: =D37 -> 18 | J37: =F37 -> 701
D38: 18 | E38: Post difference outsourcing702 | F38: 702 | G38: Post difference giữa tồn kho thực tế và hệ thống của kho nhà thầu phụ | H38: Out | K38: =F38 -> 702
D39: 19 | E39: Production rejects555 | F39: 555 | G39: Hàng hỏng do sản xuất | H39: Out | K39: =F39 -> 555
D40: 19 | E40: Production rejects556 | F40: 556 | G40: Hàng hỏng do sản xuất | H40: In | I40: =D40 -> 19 | J40: =F40 -> 556
...
