Workbook

Sheet Sheet1
A1: TypeRQ | B1: Material | C1: Roh_Halb | D1: Sloc | E1: Qty | F1: STprice | G1: ActualPrice | H1: Mvtype | I1: MVContent | J1: Plant | K1: CostCenter | L1: NameCode | M1: Reason | N1: VendorCode | O1: Note | P1: CountryofOrigin | Q1: ItemDecription | R1: RQ_Reset | S1: TypeSapPMS
A2: 15.2 | B2: PNBC1354ZA1K108/V1 | C2: Roh | D2: 1D88 | E2: 8 | F2: 0.0189 | G2: 0.1512 | H2: 702 | I2: =VLOOKUP(H2,'Master(Ko Xóa)'!$F$2:$H$158,3,0) -> Out | J2: VR01 | K2: 1ADB00 | L2: TEL | M2: Shortage in Line but cannot claim Vendor | S2: Other
A3: 15.2 | B3: PNBC1563ZA1K108/V2 | C3: Roh | D3: 1D88 | E3: 7 | F3: 0.0516 | G3: 0.3612 | H3: 702 | I3: =VLOOKUP(H3,'Master(Ko Xóa)'!$F$2:$H$158,3,0) -> Out | J3: VR01 | K3: 1ADB00 | L3: TEL | M3: Shortage in Line but cannot claim Vendor | S3: Other
A4: 15.2 | B4: PNBC1593ZA1K108/M1 | C4: Roh | D4: 1D88 | E4: 10 | F4: 0.0279 | G4: 0.279 | H4: 702 | I4: =VLOOKUP(H4,'Master(Ko Xóa)'!$F$2:$H$158,3,0) -> Out | J4: VR01 | K4: 1ADB00 | L4: TEL | M4: Shortage in Line but cannot claim Vendor | S4: Other
A5: 15.2 | B5: PNBC1594ZA1K108/M1 | C5: Roh | D5: 1D88 | E5: 24 | F5: 0.0461 | G5: 1.1064 | H5: 702 | I5: =VLOOKUP(H5,'Master(Ko Xóa)'!$F$2:$H$158,3,0) -> Out | J5: VR01 | K5: 1ADB00 | L5: TEL | M5: Shortage in Line but cannot claim Vendor | S5: Other
A6: 15.2 | B6: PNGP1138ZB1C100/V2 | C6: Roh | D6: 1D88 | E6: 23 | F6: 0.11847 | G6: 2.72481 | H6: 702 | I6: =VLOOKUP(H6,'Master(Ko Xóa)'!$F$2:$H$158,3,0) -> Out | J6: VR01 | K6: 1ADB00 | L6: TEL | M6: Shortage in Line but cannot claim Vendor | S6: Other
A7: 15.2 | B7: PNGP1138ZB2C100/V2 | C7: Roh | D7: 1D88 | E7: 4 | F7: 0.13497 | G7: 0.53988 | H7: 702 | I7: =VLOOKUP(H7,'Master(Ko Xóa)'!$F$2:$H$158,3,0) -> Out | J7: VR01 | K7: 1ADB00 | L7: TEL | M7: Shortage in Line but cannot claim Vendor | S7: Other
A8: 15.2 | B8: PNGP1331XA9C100/V2 | C8: Roh | D8: 1D88 | E8: 4 | F8: 0.1059 | G8: 0.4236 | H8: 702 | I8: =VLOOKUP(H8,'Master(Ko Xóa)'!$F$2:$H$158,3,0) -> Out | J8: VR01 | K8: 1ADB00 | L8: TEL | M8: Shortage in Line but cannot claim Vendor | S8: Other
A9: 15.2 | B9: PNGP1331ZAAC100/V2 | C9: Roh | D9: 1D88 | E9: 2 | F9: 0.1053 | G9: 0.2106 | H9: 702 | I9: =VLOOKUP(H9,'Master(Ko Xóa)'!$F$2:$H$158,3,0) -> Out | J9: VR01 | K9: 1ADB00 | L9: TEL | M9: Shortage in Line but cannot claim Vendor | S9: Other
A10: 15.2 | B10: PNGP1349ZA1C100/V1 | C10: Roh | D10: 1D88 | E10: 2 | F10: 0.0913 | G10: 0.1826 | H10: 702 | I10: =VLOOKUP(H10,'Master(Ko Xóa)'!$F$2:$H$158,3,0) -> Out | J10: VR01 | K10: 1ADB00 | L10: TEL | M10: Shortage in Line but cannot claim Vendor | S10: Other
A11: 15.2 | B11: PNGP1363ZA1C100/M1 | C11: Roh | D11: 1D88 | E11: 11 | F11: 0.0306 | G11: 0.3366 | H11: 702 | I11: =VLOOKUP(H11,'Master(Ko Xóa)'!$F$2:$H$158,3,0) -> Out | J11: VR01 | K11: 1ADB00 | L11: TEL | M11: Shortage in Line but cannot claim Vendor | S11: Other
A12: 15.2 | B12: PNGP1364ZA1C100/V1 | C12: Roh | D12: 1D88 | E12: 40 | F12: 0.1399 | G12: 5.596 | H12: 702 | I12: =VLOOKUP(H12,'Master(Ko Xóa)'!$F$2:$H$158,3,0) -> Out | J12: VR01 | K12: 1ADB00 | L12: TEL | M12: Shortage in Line but cannot claim Vendor | S12: Other
A13: 15.2 | B13: PNGTB123ZA/V1 | C13: Roh | D13: 1D88 | E13: 6 | F13: 0.0091 | G13: 0.0546 | H13: 702 | I13: =VLOOKUP(H13,'Master(Ko Xóa)'!$F$2:$H$158,3,0) -> Out | J13: VR01 | K13: 1ADB00 | L13: TEL | M13: Shortage in Line but cannot claim Vendor | S13: Other
... A76: 15.2 | B76: XZB13X19C03/V1 | C76: Roh | D76: 1D88 | E76: 70 | F76: 0.0031 | G76: 0.217 | H76: 702 | I76: =VLOOKUP(H76,'Master(Ko Xóa)'!$F$2:$H$158,3,0) -> Out | J76: VR01 | K76: 1ADB00 | L76: TEL | M76: Shortage in Line but cannot claim Vendor | S76: Other

Sheet Master(Ko Xóa)
A1: TypeID | D1: TypeID | E1: MVTypeName | G1: Decription | H1: ContentMV
A2: 1 | D2: 1 | E2: Other issue materials201 | F2: 201 | G2: Xuất/Nhập NVL cho mục đích như Gửi hàng mẫu, làm JIG, check ROSH, phân tích, check Assembly,… | H2: Out | K2: =F2 -> 201 | N2: MVTypeName | O2: =VLOOKUP(Sheet1!#REF!,'Master(Ko Xóa)'!$D$2:$K$158,8,0) -> #REF! | Q2: Sub
A3: 2 | D3: 1 | E3: Other issue materials202 | F3: 202 | G3: Xuất/Nhập NVL cho mục đích như Gửi hàng mẫu, làm JIG, check ROSH, phân tích, check Assembly,… | H3: In | I3: =D3 -> 1 | J3: =F3 -> 202 | O3: =VLOOKUP(Sheet1!#REF!,'Master(Ko Xóa)'!$I$3:$J$147,2,0) -> #REF! | Q3: Other
A4: 3 | D4: 2 | E4: Return materials291 | F4: 291 | G4: Hàng trả lại vendor (Issue debit note) | H4: Out | K4: =F4 -> 291 | Q4: Scrap
A5: 4.1 | D5: 2 | E5: Return materials292 | F5: 292 | G5: Hàng trả lại vendor (Issue debit note) | H5: In | I5: =D5 -> 2 | J5: =F5 -> 292 | Q5: Sloc98
A6: 4.2 | D6: 3 | E6: Material shortage201 | F6: 201 | G6: Vendor giao hàng thiếu (Issue debit note) | H6: Out | K6: =F6 -> 201
A7: 5.1 | D7: 3 | E7: Material shortage202 | F7: 202 | G7: Vendor giao hàng thiếu (Issue debit note) | H7: In | I7: =D7 -> 3 | J7: =F7 -> 202
A8: 5.2 | D8: 4 | E8: Claim scrap material201 | F8: 201 | G8: Hàng mua từ vendor nhưng NG không trả lại cho vendor, scrap tại PSNV (Issue debit note) | H8: Out | K8: =F8 -> 201
A9: 6 | D9: 4 | E9: Claim scrap material202 | F9: 202 | G9: Hàng mua từ vendor nhưng NG không trả lại cho vendor, scrap tại PSNV (Issue debit note) | H9: In | I9: =D9 -> 4 | J9: =F9 -> 202
A10: 7 | D10: 5 | E10: Claim Scrap Material (Claim transportation compa | F10: mpa | G10: Hàng mua từ vendor nhưng NG do bên vận chuyển, đòi tiền bên vận chuyển | H10: Out | K10: =F10 -> mpa
A11: 8 | D11: 5 | E11: Claim Scrap Material (Claim transportation compa | F11: mpa | G11: Hàng mua từ vendor nhưng NG do bên vận chuyển, đòi tiền bên vận chuyển | H11: In | I11: =D11 -> 5 | J11: =F11 -> mpa
A12: 9 | D12: 6 | E12: Disposition551 | F12: 551 | G12: Hàng NVL hủy do PSNV chịu chi phí | H12: Out | K12: =F12 -> 551
A13: 10 | D13: 6 | E13: Disposition552 | F13: 552 | G13: Hàng NVL hủy do PSNV chịu chi phí | H13: In | I13: =D13 -> 6 | J13: =F13 -> 552
A14: 11 | D14: 7 | E14: Claim scrap halb201 | F14: 201 | G14: Hàng halb bị hỏng do NVL mua từ vendor bị hỏng và scrap tại PSNV (Issue debit note) | H14: Out | K14: =F14 -> 201
A15: 12 | D15: 7 | E15: Claim scrap halb202 | F15: 202 | G15: Hàng halb bị hỏng do NVL mua từ vendor bị hỏng và scrap tại PSNV (Issue debit note) | H15: In | I15: =D15 -> 7 | J15: =F15 -> 202
A16: 13.1 | D16: 8 | E16: Claim scrap deadstock201 | F16: 201 | G16: Hàng NVL mua của 1 vendor và không dùng nữa vendor khác chịu chi phí và hủy tại PSNV | H16: Out | K16: =F16 -> 201
A17: 13.2 | D17: 8 | E17: Claim scrap deadstock202 | F17: 202 | G17: Hàng NVL mua của 1 vendor và không dùng nữa vendor khác chịu chi phí và hủy tại PSNV | H17: In | I17: =D17 -> 8 | J17: =F17 -> 202
A18: 13.3 | D18: 9 | E18: Issue for lending201 | F18: 201 | G18: Xuất HALB cho vendor, sau đó, hàng trả về PSNV và đòi tiền vendor theo Claim scrap half (hợp đồng Lending và General Sanction) | H18: Out | K18: =F18 -> 201
A19: 13.4 | D19: 9 | E19: Issue for lending202 | F19: 202 | G19: Xuất HALB cho vendor, sau đó, hàng trả về PSNV và đòi tiền vendor theo Claim scrap half (hợp đồng Lending và General Sanction) | H19: In | I19: =D19 -> 9 | J19: =F19 -> 202
A20: 14 | D20: 10 | E20: Sale deadstock201 | F20: 201 | G20: Hàng NVL mua của 1 vendor và không dùng nữa nên xuất bán cho 1 vendor khác | H20: Out | K20: =F20 -> 201
A21: 15.1 | D21: 10 | E21: Sale deadstock202 | F21: 202 | G21: Hàng NVL mua của 1 vendor và không dùng nữa nên xuất bán cho 1 vendor khác | H21: In | I21: =D21 -> 10 | J21: =F21 -> 202
A22: 15.2 | D22: 11 | E22: Compensation201 | F22: 201 | G22: Hàng NVL mua về nhưng không dùng do sai thiết kế, vendor chịu chi phí, hủy tại PSNV | H22: Out | K22: =F22 -> 201
A23: 16.1 | D23: 11 | E23: Compensation202 | F23: 202 | G23: Hàng NVL mua về nhưng không dùng do sai thiết kế, vendor chịu chi phí, hủy tại PSNV | H23: In | I23: =D23 -> 11 | J23: =F23 -> 202
A24: 16.2 | D24: 12 | E24: Outsourcing201 | F24: 201 | G24: Hàng NVL issue out dùng cho outsourcing | H24: Out | K24: =F24 -> 201
A25: 17.1 | D25: 12 | E25: Outsourcing202 | F25: 202 | G25: Hàng NVL issue out dùng cho outsourcing | H25: In | I25: =D25 -> 12 | J25: =F25 -> 202
A26: 17.2 | D26: 13 | E26: Claim insurance201 | F26: 201 | G26: Hàng NVL bị hỏng trong quá trình vận chuyển và được bồi thường bảo hiểm | H26: Out | K26: =F26 -> 201
A27: 18.1 | D27: 13 | E27: Claim insurance202 | F27: 202 | G27: Hàng NVL bị hỏng trong quá trình vận chuyển và được bồi thường bảo hiểm | H27: In | I27: =D27 -> 13 | J27: =F27 -> 202
A28: 18.2 | D28: 14 | E28: Issue out for rework201 | F28: 201 | G28: Hàng NVL issue out để reworks (Issue Debitnote) | H28: Out | K28: =F28 -> 201
A29: 19 | D29: 14 | E29: Issue out for rework202 | F29: 202 | G29: Hàng NVL issue out để reworks (Issue Debitnote) | H29: In | I29: =D29 -> 14 | J29: =F29 -> 202
A30: 20 | D30: 15 | E30: Issue Out For Rework (Not issue Debit Note)201 | F30: 201 | G30: Hàng NVL issue out cho reworks (không Issue Debitnote), hủy tại PSNV | H30: Out | K30: =F30 -> 201
A31: 21 | D31: 15 | E31: Issue Out For Rework (Not issue Debit Note)202 | F31: 202 | G31: Hàng NVL issue out cho reworks (không Issue Debitnote), hủy tại PSNV | H31: In | I31: =D31 -> 15 | J31: =F31 -> 202
A32: 22 | D32: 16 | E32: Issue sub-materials201 | F32: 201 | G32: Issue NVL phụ cho sản xuất thành phẩm | H32: Out | K32: =F32 -> 201
A33: 23 | D33: 16 | E33: Issue sub-materials202 | F33: 202 | G33: Issue NVL phụ cho sản xuất thành phẩm | H33: In | I33: =D33 -> 16 | J33: =F33 -> 202
A34: 24 | D34: 16 | E34: Issue Sub-Materials201 | F34: 201 | G34: Issue NVL phụ cho sản xuất thành phẩm | H34: Out | K34: =F34 -> 201
D35: 17 | E35: Post difference end of month701 | F35: 701 | G35: Post difference giữa tồn kho thực tế và hệ thống | H35: In | I35: =D35 -> 17 | J35: =F35 -> 701
D36: 17 | E36: Post difference end of month702 | F36: 702 | G36: Post difference giữa tồn kho thực tế và hệ thống | H36: Out | K36: =F36 -> 702
D37: 18 | E37: Post difference outsourcing701 | F37: 701 | G37: Post difference giữa tồn kho thực tế và hệ thống của kho nhà thầu phụ | H37: In | I37: =D37 -> 18 | J37: =F37 -> 701
D38: 18 | E38: Post difference outsourcing702 | F38: 702 | G38: Post difference giữa tồn kho thực tế và hệ thống của kho nhà thầu phụ | H38: Out | K38: =F38 -> 702
D39: 19 | E39: Production rejects555 | F39: 555 | G39: Hàng hỏng do sản xuất | H39: Out | K39: =F39 -> 555
D40: 19 | E40: Production rejects556 | F40: 556 | G40: Hàng hỏng do sản xuất | H40: In | I40: =D40 -> 19 | J40: =F40 -> 556
...
